<?xml version="1.0" ?>
<!-- =================================================================================== -->
<!-- |    This document was autogenerated by xacro from jackal.urdf.xacro              | -->
<!-- |    EDITING THIS FILE BY HAND IS NOT RECOMMENDED                                 | -->
<!-- =================================================================================== -->
<robot name="jackal" xmlns:xacro="http://www.ros.org/wiki/xacro">
  <material name="dark_grey">
    <color rgba="0.2 0.2 0.2 1.0"/>
  </material>
  <material name="light_grey">
    <color rgba="0.4 0.4 0.4 1.0"/>
  </material>
  <material name="yellow">
    <color rgba="0.8 0.8 0.0 1.0"/>
  </material>
  <material name="black">
    <color rgba="0.15 0.15 0.15 1.0"/>
  </material>
  <link name="front_left_wheel_link">
    <visual>
      <origin rpy="1.57079632679 0 0" xyz="0 0 0"/>
      <geometry>
        <mesh filename="package://jackal_description/meshes/jackal-wheel.stl"/>
      </geometry>
      <material name="black"/>
    </visual>
    <collision>
      <origin rpy="1.57079632679 0 0" xyz="0 0 0"/>
      <geometry>
        <cylinder length="0.04" radius="0.098"/>
      </geometry>
    </collision>
    <inertial>
      <origin rpy="0 0 0" xyz="0 0 0"/>
      <mass value="0.477"/>
      <inertia ixx="0.0013" ixy="0" ixz="0" iyy="0.0024" iyz="0" izz="0.0013"/>
    </inertial>
  </link>
  <gazebo reference="front_left_wheel_link">
    <material>Gazebo/DarkGrey</material>
  </gazebo>
  <joint name="front_left_wheel" type="continuous">
    <parent link="chassis_link"/>
    <child link="front_left_wheel_link"/>
    <origin rpy="0 0 0" xyz="0.131 0.187795 0.0345"/>
    <axis xyz="0 1 0"/>
  </joint>
  <!-- In reality, Jackal has only two motors, one per side. However, it's more
         straightforward for Gazebo to simulate as if there's an actuator per wheel. -->
  <transmission name="front_left_wheel_trans">
    <type>transmission_interface/SimpleTransmission</type>
    <joint name="front_left_wheel">
      <hardwareInterface>VelocityJointInterface</hardwareInterface>
    </joint>
    <actuator name="front_left_actuator">
      <mechanicalReduction>1</mechanicalReduction>
    </actuator>
  </transmission>
  <link name="front_right_wheel_link">
    <visual>
      <origin rpy="1.57079632679 0 0" xyz="0 0 0"/>
      <geometry>
        <mesh filename="package://jackal_description/meshes/jackal-wheel.stl"/>
      </geometry>
      <material name="black"/>
    </visual>
    <collision>
      <origin rpy="1.57079632679 0 0" xyz="0 0 0"/>
      <geometry>
        <cylinder length="0.04" radius="0.098"/>
      </geometry>
    </collision>
    <inertial>
      <origin rpy="0 0 0" xyz="0 0 0"/>
      <mass value="0.477"/>
      <inertia ixx="0.0013" ixy="0" ixz="0" iyy="0.0024" iyz="0" izz="0.0013"/>
    </inertial>
  </link>
  <gazebo reference="front_right_wheel_link">
    <material>Gazebo/DarkGrey</material>
  </gazebo>
  <joint name="front_right_wheel" type="continuous">
    <parent link="chassis_link"/>
    <child link="front_right_wheel_link"/>
    <origin rpy="0 0 0" xyz="0.131 -0.187795 0.0345"/>
    <axis xyz="0 1 0"/>
  </joint>
  <!-- In reality, Jackal has only two motors, one per side. However, it's more
         straightforward for Gazebo to simulate as if there's an actuator per wheel. -->
  <transmission name="front_right_wheel_trans">
    <type>transmission_interface/SimpleTransmission</type>
    <joint name="front_right_wheel">
      <hardwareInterface>VelocityJointInterface</hardwareInterface>
    </joint>
    <actuator name="front_right_actuator">
      <mechanicalReduction>1</mechanicalReduction>
    </actuator>
  </transmission>
  <link name="rear_left_wheel_link">
    <visual>
      <origin rpy="1.57079632679 0 0" xyz="0 0 0"/>
      <geometry>
        <mesh filename="package://jackal_description/meshes/jackal-wheel.stl"/>
      </geometry>
      <material name="black"/>
    </visual>
    <collision>
      <origin rpy="1.57079632679 0 0" xyz="0 0 0"/>
      <geometry>
        <cylinder length="0.04" radius="0.098"/>
      </geometry>
    </collision>
    <inertial>
      <origin rpy="0 0 0" xyz="0 0 0"/>
      <mass value="0.477"/>
      <inertia ixx="0.0013" ixy="0" ixz="0" iyy="0.0024" iyz="0" izz="0.0013"/>
    </inertial>
  </link>
  <gazebo reference="rear_left_wheel_link">
    <material>Gazebo/DarkGrey</material>
  </gazebo>
  <joint name="rear_left_wheel" type="continuous">
    <parent link="chassis_link"/>
    <child link="rear_left_wheel_link"/>
    <origin rpy="0 0 0" xyz="-0.131 0.187795 0.0345"/>
    <axis xyz="0 1 0"/>
  </joint>
  <!-- In reality, Jackal has only two motors, one per side. However, it's more
         straightforward for Gazebo to simulate as if there's an actuator per wheel. -->
  <transmission name="rear_left_wheel_trans">
    <type>transmission_interface/SimpleTransmission</type>
    <joint name="rear_left_wheel">
      <hardwareInterface>VelocityJointInterface</hardwareInterface>
    </joint>
    <actuator name="rear_left_actuator">
      <mechanicalReduction>1</mechanicalReduction>
    </actuator>
  </transmission>
  <link name="rear_right_wheel_link">
    <visual>
      <origin rpy="1.57079632679 0 0" xyz="0 0 0"/>
      <geometry>
        <mesh filename="package://jackal_description/meshes/jackal-wheel.stl"/>
      </geometry>
      <material name="black"/>
    </visual>
    <collision>
      <origin rpy="1.57079632679 0 0" xyz="0 0 0"/>
      <geometry>
        <cylinder length="0.04" radius="0.098"/>
      </geometry>
    </collision>
    <inertial>
      <origin rpy="0 0 0" xyz="0 0 0"/>
      <mass value="0.477"/>
      <inertia ixx="0.0013" ixy="0" ixz="0" iyy="0.0024" iyz="0" izz="0.0013"/>
    </inertial>
  </link>
  <gazebo reference="rear_right_wheel_link">
    <material>Gazebo/DarkGrey</material>
  </gazebo>
  <joint name="rear_right_wheel" type="continuous">
    <parent link="chassis_link"/>
    <child link="rear_right_wheel_link"/>
    <origin rpy="0 0 0" xyz="-0.131 -0.187795 0.0345"/>
    <axis xyz="0 1 0"/>
  </joint>
  <!-- In reality, Jackal has only two motors, one per side. However, it's more
         straightforward for Gazebo to simulate as if there's an actuator per wheel. -->
  <transmission name="rear_right_wheel_trans">
    <type>transmission_interface/SimpleTransmission</type>
    <joint name="rear_right_wheel">
      <hardwareInterface>VelocityJointInterface</hardwareInterface>
    </joint>
    <actuator name="rear_right_actuator">
      <mechanicalReduction>1</mechanicalReduction>
    </actuator>
  </transmission>
  <link name="base_link"/>
  <joint name="base_link_joint" type="fixed">
    <origin rpy="0 0 0" xyz="0 0 0"/>
    <parent link="base_link"/>
    <child link="chassis_link"/>
  </joint>
  <link name="chassis_link">
    <visual>
      <origin rpy="1.57079632679 0 1.57079632679" xyz="0 0 -0.0655"/>
      <geometry>
        <mesh filename="package://jackal_description/meshes/jackal-base.stl"/>
      </geometry>
      <material name="dark_grey"/>
    </visual>
    <collision>
      <origin xyz="0 0 0.092"/>
      <geometry>
        <box size="0.42 0.31 0.184"/>
      </geometry>
    </collision>
    <inertial>
      <!-- Center of mass -->
      <origin rpy="0 0 0" xyz="0.012  0.002 0.067"/>
      <mass value="16.523"/>
      <!-- Moments of inertia: ( chassis without wheels ) -->
      <inertia ixx="0.3136" ixy="-0.0008" ixz="0.0164" iyy="0.3922" iyz="-0.0009" izz="0.4485"/>
    </inertial>
  </link>
  <link name="fenders_link">
    <visual>
      <origin rpy="1.57079632679 0 1.57079632679" xyz="0 0 -0.0655"/>
      <geometry>
        <mesh filename="package://jackal_description/meshes/jackal-fenders.stl"/>
      </geometry>
      <material name="yellow"/>
    </visual>
  </link>
  <joint name="fenders_joint" type="fixed">
    <parent link="chassis_link"/>
    <child link="fenders_link"/>
  </joint>

<!-- ==================================================== -->
<!-- ============== KINECT PLACEMENT ==================== -->

  <link name="box_link">
    <visual>
      <geometry>
        <box size="0.05 0.08 0.25"/>
      </geometry>
      <material name="pink">
        <color rgba="1 0.2 0.2 1"/>
      </material>
    </visual>
  </link>
  <joint name="box_joint" type="fixed">
    <parent link="fenders_link"/>
    <child link="box_link"/>
    <origin xyz="0 0.0 0.3" rpy="0 0 0" />
  </joint>
  <gazebo reference="box_link">
    <material><color rgba="1 0.2 0.2 1"/></material>
    <turnGravityOff>false</turnGravityOff>
  </gazebo>

<link name="kinect_link">
  <visual>
    <geometry>
      <box size="0.064 0.121 0.0381" />
    </geometry>
      <material name="pink">
        <color rgba="1 0.2 0.2 1"/>
      </material>
  </visual>
  <inertial>
      <mass value="0.0001" />
      <origin xyz="0 0 0" />
      <inertia ixx="0.0001" ixy="0.0" ixz="0.0"
               iyy="0.0001" iyz="0.0" 
               izz="0.0001" />
  </inertial>
</link>
  <gazebo reference="kinect_link">
    <material><color rgba="1 0.2 0.2 1"/></material>
    <turnGravityOff>false</turnGravityOff>
  </gazebo>

  <joint name="kinect_joint" type="fixed">
    <parent link="box_link"/>
    <child link="kinect_link"/>
    <origin xyz="0 0.0 0.15" rpy="0 0 0" />
  </joint>

<link name="kinect_depth_frame">
  <inertial>
      <mass value="0.0001" />
      <origin xyz="0 0 0" />
      <inertia ixx="0.0001" ixy="0.0" ixz="0.0"
               iyy="0.0001" iyz="0.0" 
               izz="0.0001" />
  </inertial>
</link>

<joint name="kinect_depth_joint" type="fixed">
  <origin xyz="0 0.028 0" rpy="0 0 0" />
  <parent link="kinect_link" />
  <child link="kinect_depth_frame" />
</joint>

<link name="kinect_depth_optical_frame">
  <inertial>
      <mass value="0.0001" />
      <origin xyz="0 0 0" />
      <inertia ixx="0.0001" ixy="0.0" ixz="0.0"
               iyy="0.0001" iyz="0.0" 
               izz="0.0001" />
  </inertial>
</link>

<joint name="depth_optical_joint" type="fixed">
  <origin xyz="0 0 0" />
  <parent link="kinect_depth_frame" />
  <child link="kinect_depth_optical_frame" />
</joint>

<!-- ==================================================== -->

  <!-- TODO: Make this internal_imu_link or something, and use a mixed-in xacro
       to supply the joint between it and imu_link. This is important so that imu_link
       always points to the "active" IMU. When an upgrade IMU is connected, the
       internal_imu_link should remain, but imu_link should point to the upgrade one. -->
  <link name="imu_link">
    <inertial>
      <mass value="0.001"/>
      <origin rpy="0 0 0" xyz="0 0 0"/>
      <inertia ixx="1e-09" ixy="0.0" ixz="0.0" iyy="1e-09" iyz="0.0" izz="1e-09"/>
    </inertial>
  </link>
  <joint name="imu_joint" type="fixed">
    <parent link="chassis_link"/>
    <child link="imu_link"/>
  </joint>
  <!-- TODO: Same note as applies to imu_link -->
  <link name="navsat_link">
    <visual>
      <geometry>
        <cylinder length="0.016" radius="0.026"/>
      </geometry>
      <origin xyz="0 0 0.008"/>
      <material name="black"/>
    </visual>
  </link>
  <joint name="navsat_joint" type="fixed">
    <parent link="chassis_link"/>
    <child link="navsat_link"/>
    <origin xyz="-0.180 0.126 0.1815"/>
  </joint>
  <link name="mid_mount"/>
  <joint name="mid_mount_joint" type="fixed">
    <parent link="chassis_link"/>
    <child link="mid_mount"/>
    <origin xyz="0 0 0.184"/>
  </joint>
  <link name="rear_mount"/>
  <joint name="rear_mount_joint" type="fixed">
    <parent link="mid_mount"/>
    <child link="rear_mount"/>
    <origin xyz="-0.12 0 0"/>
  </joint>
  <link name="front_mount"/>
  <joint name="front_mount_joint" type="fixed">
    <parent link="mid_mount"/>
    <child link="front_mount"/>
    <origin xyz="0.12 0 0"/>
  </joint>
  <!-- Bring in simulation data for Gazebo. -->
  <gazebo>
    <plugin filename="libgazebo_ros_control.so" name="gazebo_ros_control">
      <robotNamespace>/</robotNamespace>
    </plugin>
  </gazebo>
  <gazebo>
    <plugin filename="libhector_gazebo_ros_imu.so" name="imu_controller">
      <robotNamespace>/</robotNamespace>
      <updateRate>50.0</updateRate>
      <bodyName>imu_link</bodyName>
      <topicName>imu/data</topicName>
      <accelDrift>0.005 0.005 0.005</accelDrift>
      <accelGaussianNoise>0.005 0.005 0.005</accelGaussianNoise>
      <rateDrift>0.005 0.005 0.005 </rateDrift>
      <rateGaussianNoise>0.005 0.005 0.005 </rateGaussianNoise>
      <headingDrift>0.005</headingDrift>
      <headingGaussianNoise>0.005</headingGaussianNoise>
    </plugin>
  </gazebo>
  <gazebo>
    <plugin filename="libhector_gazebo_ros_gps.so" name="gps_controller">
      <updateRate>40</updateRate>
      <robotNamespace>/</robotNamespace>
      <bodyName>navsat_link</bodyName>
      <frameId>base_link</frameId>
      <topicName>/navsat/fix</topicName>
      <velocityTopicName>/navsat/vel</velocityTopicName>
      <referenceLatitude>49.9</referenceLatitude>
      <referenceLongitude>8.9</referenceLongitude>
      <referenceHeading>0</referenceHeading>
      <referenceAltitude>0</referenceAltitude>
      <drift>0.0001 0.0001 0.0001</drift>
    </plugin>
  </gazebo>
  <gazebo reference="base_link">
    <turnGravityOff>false</turnGravityOff>
  </gazebo>
  <gazebo reference="chassis_link">
    <material>Gazebo/DarkGrey</material>
    <turnGravityOff>false</turnGravityOff>
  </gazebo>
  <gazebo reference="imu_link">
    <turnGravityOff>false</turnGravityOff>
  </gazebo>
  <gazebo reference="navsat_link">
    <material>Gazebo/DarkGrey</material>
    <turnGravityOff>false</turnGravityOff>
  </gazebo>
  <gazebo reference="fenders_link">
    <material>Gazebo/Yellow</material>
    <turnGravityOff>false</turnGravityOff>
  </gazebo>

  <!-- Optional standard accessories, including their simulation data. The rendering
       of these into the final description is controlled by optenv variables, which
       default each one to off.-->
  <!--
    As you add to this URDF, please be aware that both the robot and
    simulation include it. You must retain compatibility with all of
    the following launch files:

    jackal_viz/launch/view_model.launch
    jackal_gazebo/launch/jackal_world.launch
    jackal_base/launch/base.launch
  -->
  <!-- Macros to generate standoffs for offset payload mounting. -->
  <!-- Generate a single payload plate standoff. -->
  <!-- Generate a set of four standoffs from a payload mount point. -->
  <!-- This optional plate mounts both the upgraded GPS and the Velodyne 3D LIDAR. -->
  <!-- If enabled, generate the LASER payload (by default, a SICK LMS111). -->
  <link name="front_laser">
    <inertial>
      <mass value="1.1"/>
      <origin xyz="0 0 0"/>
      <inertia ixx="0.00307156543804" ixy="0.0" ixz="0.0" iyy="0.00312849041527" iyz="0.0" izz="0.00196432421427"/>
    </inertial>
    <visual>
      <origin rpy="0 0 0" xyz="0 0 0"/>
      <geometry>
        <!-- Origin of this mesh is the focal point of the LIDAR. -->
        <mesh filename="package://lms1xx/meshes/sick-lms1xx.dae"/>
      </geometry>
    </visual>
    <collision>
      <origin rpy="0 0 0" xyz="0 0 -0.05"/>
      <geometry>
        <box size="0.105 0.1 0.1"/>
      </geometry>
    </collision>
  </link>
  <gazebo reference="front_laser">
    <turnGravityOff>true</turnGravityOff>
    <sensor name="front_laser" type="ray">
      <pose>0 0 0 0 0 0</pose>
      <visualize>false</visualize>
      <update_rate>50</update_rate>
      <ray>
        <scan>
          <horizontal>
            <samples>720</samples>
            <resolution>1</resolution>
            <min_angle>-2.35619</min_angle>
            <max_angle>2.35619</max_angle>
          </horizontal>
        </scan>
        <range>
          <min>0.1</min>
          <max>30.0</max>
          <resolution>0.01</resolution>
        </range>
        <noise>
          <type>gaussian</type>
          <mean>0.0</mean>
          <stddev>0.001</stddev>
        </noise>
      </ray>
      <plugin filename="libgazebo_ros_laser.so" name="gazebo_ros_laser">
        <topicName>front/scan</topicName>
        <frameName>front_laser</frameName>
        <robotNamespace>/</robotNamespace>
      </plugin>
    </sensor>
  </gazebo>
  <link name="front_laser_mount">
    <visual>
      <origin rpy="0 0 0" xyz="0 0 0"/>
      <geometry>
        <!-- Origin of this mesh is the base of the bracket. -->
        <mesh filename="package://jackal_description/meshes/sick-lms1xx-bracket.stl"/>
      </geometry>
      <material name="dark_grey"/>
    </visual>
  </link>
  <joint name="front_laser_joint" type="fixed">
    <!-- This offset is from the base of the bracket to the LIDAR's focal point. -->
    <origin rpy="0 0 0" xyz="0 0 0.149"/>
    <parent link="front_laser_mount"/>
    <child link="front_laser"/>
  </joint>
  <gazebo reference="front_laser_mount">
    <material>Gazebo/DarkGrey</material>
  </gazebo>
  <joint name="front_laser_mount_joint" type="fixed">
    <origin rpy="0 0 0" xyz="0 0 0"/>
    <parent link="front_mount"/>
    <child link="front_laser_mount"/>
  </joint>
  <!-- If enabled, generate the upgraded Navsat payload (a Novatel Smart6). -->
  <!-- If enabled, generate the flea3 camera payload with a tilt of 30 degrees. -->
  <!--<xacro:include filename="accessories/camera_mount.urdf.xacro" />
  <xacro:include filename="$(find pointgrey_camera_description)/urdf/pointgrey_flea3.urdf.xacro" />

    <camera_mount prefix="$(optenv JACKAL_FLEA3_MOUNT front)"
                       tilt="$(optenv JACKAL_FLEA3_TILT 0.5236)"/>
    <joint name="$(optenv JACKAL_FLEA3_MOUNT front)_camera_mount_joint" type="fixed">
      <origin xyz="$(optenv JACKAL_FLEA3_OFFSET 0 0 0)"
              rpy="$(optenv JACKAL_FLEA3_RPY 0 0 0)" />
      <parent link="$(optenv JACKAL_FLEA3_MOUNT front)_mount" />
      <child link="$(optenv JACKAL_FLEA3_MOUNT front)_camera_mount" />
    </joint>

    <pointgrey_flea3 frame="$(optenv JACKAL_FLEA3_MOUNT front)_camera" name="$(optenv JACKAL_FLEA3_NAME front)"
      camera_x="0.0754" camera_y="0.029" camera_z="0.035"
      camera_mass="0.085" hfov="1.0471975512" fps="60" width="640" height="512"/>
    <joint name="$(optenv JACKAL_FLEA3_MOUNT front)_camera_bracket_joint" type="fixed">
      <origin xyz="0.020 0 0.0245" rpy="0 0 0" />
      <parent link="$(optenv JACKAL_FLEA3_MOUNT front)_camera_beam" />
      <child link="$(optenv JACKAL_FLEA3_MOUNT front)_camera" />
    </joint>-->
  <!-- If enabled, generate the bumblebee2 camera payload with a tilt of 0 degrees. -->
  <!-- <xacro:if value="$(optenv JACKAL_BB2 0)">-->
  <link name="front_camera_mount">
    <visual>
      <origin rpy="1.5707 0 1.5707" xyz="0 0 0"/>
      <geometry>
        <mesh filename="package://jackal_description/meshes/camera-bracket.stl" scale="0.001 0.001 0.001"/>
      </geometry>
      <material name="dark_grey"/>
    </visual>
  </link>
  <link name="front_camera_beam">
    <visual>
      <origin rpy="0 0 1.5707" xyz="0 0 0"/>
      <geometry>
        <mesh filename="package://jackal_description/meshes/camera-beam.stl" scale="0.001 0.001 0.001"/>
      </geometry>
      <material name="dark_grey"/>
    </visual>
  </link>
  <joint name="front_camera_pivot_joint" type="fixed">
    <origin rpy="0 0 0" xyz="0.102 0 0.008"/>
    <parent link="front_camera_mount"/>
    <child link="front_camera_beam"/>
  </joint>
  <gazebo reference="front_camera_beam">
    <material>Gazebo/DarkGrey</material>
  </gazebo>
  <gazebo reference="front_camera_mount">
    <material>Gazebo/DarkGrey</material>
  </gazebo>
  <joint name="front_camera_mount_joint" type="fixed">
    <origin rpy="0 0 0" xyz="0 0 0"/>
    <parent link="front_mount"/>
    <child link="front_camera_mount"/>
  </joint>
  <link name="front_camera">
    <visual>
      <origin rpy="-1.5707 0 -1.5707" xyz="0 0 0"/>
      <geometry>
        <mesh filename="package://pointgrey_camera_description/meshes/pointgrey_bumblebee2.dae"/>
      </geometry>
    </visual>
    <collision>
      <origin rpy="0 0 0" xyz="0 0 0"/>
      <geometry>
        <box size="0.04740 0.157 0.036"/>
      </geometry>
    </collision>
    <inertial>
      <mass value="0.342"/>
      <inertia ixx="0.00010096866" ixy="0" ixz="0" iyy="0.00076652916" iyz="0" izz="0.0007394325"/>
    </inertial>
  </link>
  <link name="front_camera_optical">
    <inertial>
      <mass value="1E-5"/>
      <inertia ixx="1E-10" ixy="0" ixz="0" iyy="1E-10" iyz="0" izz="1E-10"/>
    </inertial>
  </link>
  <joint name="front_camera_optical_joint" type="fixed">
    <origin rpy="-1.570796 0 -1.570796" xyz="0 0 0"/>
    <parent link="front_camera"/>
    <child link="front_camera_optical"/>
  </joint>
  <gazebo reference="front_camera_optical">
    <sensor name="stereo_camera" type="multicamera">
      <update_rate>20</update_rate>
      <camera name="left">
        <pose>0 0 0 0 -1.5707 1.5707</pose>
        <horizontal_fov>1.15191730632</horizontal_fov>
        <image>
          <width>1024</width>
          <height>768</height>
          <format>R8G8B8</format>
        </image>
        <clip>
          <near>0.5</near>
          <far>300</far>
        </clip>
        <noise>
          <type>gaussian</type>
          <mean>0.0</mean>
          <stddev>0.007</stddev>
        </noise>
      </camera>
      <camera name="right">
        <pose>0.12 0 0 0 -1.5707 1.5707</pose>
        <horizontal_fov>1.15191730632</horizontal_fov>
        <image>
          <width>1024</width>
          <height>768</height>
          <format>R8G8B8</format>
        </image>
        <clip>
          <near>0.5</near>
          <far>300</far>
        </clip>
        <noise>
          <type>gaussian</type>
          <mean>0.0</mean>
          <stddev>0.007</stddev>
        </noise>
      </camera>
      <plugin filename="libgazebo_ros_multicamera.so" name="stereo_camera_controller">
        <alwaysOn>true</alwaysOn>
        <cameraName>front</cameraName>
        <imageTopicName>image_raw</imageTopicName>
        <cameraInfoTopicName>camera_info</cameraInfoTopicName>
        <frameName>front_camera_optical</frameName>
        <hackBaseline>0.12</hackBaseline>
        <!-- NOTE: Distortion is currently unused -->
        <distortionK1>0.0</distortionK1>
        <distortionK2>0.0</distortionK2>
        <distortionK3>0.0</distortionK3>
        <distortionT1>0.0</distortionT1>
        <distortionT2>0.0</distortionT2>
      </plugin>
    </sensor>
  </gazebo>


  <joint name="front_camera_bracket_joint" type="fixed">
    <origin rpy="0 0 0" xyz="0.007 0 0.02450"/>
    <parent link="front_camera_beam"/>
    <child link="front_camera"/>
  </joint>



  <!--</xacro:if>-->
  <!-- Optional custom includes. -->
  <!-- This file is a placeholder which is included by default from
       jackal.urdf.xacro. If a robot is being customized and requires
       additional URDF, set the JACKAL_URDF_EXTRAS environment variable
       to the full path of the file you would like included. -->
</robot>

